Workbook

Sheet Instruções
B2: Batistela Gestão Empresarial
B3: Consultoria em gestão empresarial • Florianópolis, SC
B5: Projeção Financeira 12 Meses
B6: Projeção Financeira de 12 Meses: a partir de premissas simples (receita, crescimento, custos, despesas fixas e investimentos), projete receita, margem, EBITDA, fluxo de caixa e caixa acumulado para o próximo ano em três cenários.
B8: Como usar
B9: 1. Na aba Premissas, informe o mês inicial da projeção, a receita esperada no primeiro mês, o crescimento mensal e os percentuais de custo variável e impostos.
B10: 2. Preencha as despesas fixas mensais por categoria e os investimentos planejados para cada um dos 12 meses (deixe 0 quando não houver).
B11: 3. Informe o saldo de caixa inicial (dinheiro disponível no início do mês 1).
B12: 4. Ajuste, se desejar, os parâmetros dos cenários Pessimista, Base e Otimista (ajuste no crescimento mensal e na receita inicial).
B13: 5. Escolha o cenário ativo na célula Cenário selecionado (Premissas) para ver a projeção detalhada na aba Projeção.
B14: 6. A aba Cenários compara os três cenários lado a lado (totais anuais, caixa final e menor caixa acumulado), independentemente do cenário selecionado.
B15: 7. Observe o gráfico de Caixa acumulado: se a linha ficar negativa em algum mês, será necessário capital de giro, redução de despesas ou adiamento de investimentos.
... B25: Material gratuito. Dúvidas: info@batistelaconsultoria.com | batistelaconsultoria.com

Sheet Premissas
B1: Premissas da Projeção
B2: Preencha as células em amarelo. Tudo o mais é calculado automaticamente.
B4: Parâmetros gerais
B5: Mês inicial da projeção (1º dia do mês) | C5: 46388
B6: Receita do 1º mês (R$) | C6: 60000
B7: Crescimento mensal da receita (%) | C7: 0.03
B8: Custo variável (% da receita) – mercadorias, insumos, comissões | C8: 0.38
B9: Impostos sobre a receita (%) | C9: 0.08
B10: Saldo de caixa inicial (R$) | C10: 25000
B12: Despesas fixas mensais por categoria (R$)
B13: Categoria | C13: Valor mensal (R$)
B14: Aluguel e condomínio | C14: 4500
B15: Salários e encargos | C15: 14000
B16: Pró-labore | C16: 6000
B17: Água, luz, internet e telefone | C17: 900
B18: Marketing fixo | C18: 1500
B19: Contabilidade e serviços de terceiros | C19: 1200
B20: Softwares e assinaturas | C20: 600
B21: Outras despesas fixas | C21: 1300
B22: Total de despesas fixas mensais | C22: =SUM(C14:C21) -> 30000
B24: Investimentos planejados por mês (R$)
B25: Mês | C25: Referência | D25: Investimento (R$) | E25: Descrição (opcional)
B26: Mês 1 | C26: =DATE(YEAR($C$5),MONTH($C$5)+0,1) -> 46388 | D26: 8000 | E26: Reforma / equipamentos
B27: Mês 2 | C27: =DATE(YEAR($C$5),MONTH($C$5)+1,1) -> 46419 | D27: 0
B28: Mês 3 | C28: =DATE(YEAR($C$5),MONTH($C$5)+2,1) -> 46447 | D28: 0
B29: Mês 4 | C29: =DATE(YEAR($C$5),MONTH($C$5)+3,1) -> 46478 | D29: 3500 | E29: Mobiliário
B30: Mês 5 | C30: =DATE(YEAR($C$5),MONTH($C$5)+4,1) -> 46508 | D30: 0
B31: Mês 6 | C31: =DATE(YEAR($C$5),MONTH($C$5)+5,1) -> 46539 | D31: 0
B32: Mês 7 | C32: =DATE(YEAR($C$5),MONTH($C$5)+6,1) -> 46569 | D32: 0
B33: Mês 8 | C33: =DATE(YEAR($C$5),MONTH($C$5)+7,1) -> 46600 | D33: 0
B34: Mês 9 | C34: =DATE(YEAR($C$5),MONTH($C$5)+8,1) -> 46631 | D34: 12000 | E34: Novo sistema
B35: Mês 10 | C35: =DATE(YEAR($C$5),MONTH($C$5)+9,1) -> 46661 | D35: 0
B36: Mês 11 | C36: =DATE(YEAR($C$5),MONTH($C$5)+10,1) -> 46692 | D36: 0
B37: Mês 12 | C37: =DATE(YEAR($C$5),MONTH($C$5)+11,1) -> 46722 | D37: 0
B38: Total de investimentos no ano | D38: =SUM(D26:D37) -> 23500
B40: Cenários
B41: Cenário selecionado (usado na aba Projeção) | C41: Base
B43: Cenário | C43: Ajuste no crescimento mensal (p.p.) | D43: Ajuste na receita do 1º mês (%) | E43: Crescimento mensal efetivo
B44: Pessimista | C44: -0.02 | D44: -0.1 | E44: =$C$7+C44 -> 0.01
B45: Base | C45: 0 | D45: 0 | E45: =$C$7+C45 -> 0.03
...

Sheet Projeção
A1: Projeção Financeira – 12 Meses
A2: Todos os valores são calculados a partir da aba Premissas e do cenário selecionado.
A4: Cenário ativo | B4: =Premissas!$C$41 -> Base | C4: Crescimento mensal aplicado | E4: =IFERROR(INDEX(Premissas!$C$44:$C$46,MATCH(Premissas!$C$41,Premissas!$B$44:$B$46,0)),0)+Premissas!$C$7 -> 0.03 | F4: Ajuste receita 1º mês | H4: =IFERROR(INDEX(Premissas!$D$44:$D$46,MATCH(Premissas!$C$41,Premissas!$B$44:$B$46,0)),0) -> 0
A6: Linha | B6: Mês 1 | C6: Mês 2 | D6: Mês 3 | E6: Mês 4 | F6: Mês 5 | G6: Mês 6 | H6: Mês 7 | I6: Mês 8 | J6: Mês 9 | K6: Mês 10 | L6: Mês 11 | M6: Mês 12 | N6: Total 12 meses
A7: Período | B7: =DATE(YEAR(Premissas!$C$5),MONTH(Premissas!$C$5)+0,1) -> 46388 | C7: =DATE(YEAR(Premissas!$C$5),MONTH(Premissas!$C$5)+1,1) -> 46419 | D7: =DATE(YEAR(Premissas!$C$5),MONTH(Premissas!$C$5)+2,1) -> 46447 | E7: =DATE(YEAR(Premissas!$C$5),MONTH(Premissas!$C$5)+3,1) -> 46478 | F7: =DATE(YEAR(Premissas!$C$5),MONTH(Premissas!$C$5)+4,1) -> 46508 | G7: =DATE(YEAR(Premissas!$C$5),MONTH(Premissas!$C$5)+5,1) -> 46539 | H7: =DATE(YEAR(Premissas!$C$5),MONTH(Premissas!$C$5)+6,1) -> 46569 | I7: =DATE(YEAR(Premissas!$C$5),MONTH(Premissas!$C$5)+7,1) -> 46600 | J7: =DATE(YEAR(Premissas!$C$5),MONTH(Premissas!$C$5)+8,1) -> 46631 | K7: =DATE(YEAR(Premissas!$C$5),MONTH(Premissas!$C$5)+9,1) -> 46661 | L7: =DATE(YEAR(Premissas!$C$5),MONTH(Premissas!$C$5)+10,1) -> 46692 | M7: =DATE(YEAR(Premissas!$C$5),MONTH(Premissas!$C$5)+11,1) -> 46722
A8: Receita | B8: =Premissas!$C$6*(1+$H$4) -> 60000 | C8: =B8*(1+$E$4) -> 61800 | D8: =C8*(1+$E$4) -> 63654 | E8: =D8*(1+$E$4) -> 65563.62 | F8: =E8*(1+$E$4) -> 67530.529 | G8: =F8*(1+$E$4) -> 69556.444 | H8: =G8*(1+$E$4) -> 71643.138 | I8: =H8*(1+$E$4) -> 73792.432 | J8: =I8*(1+$E$4) -> 76006.205 | ... M8: =L8*(1+$E$4) -> 83054.032 | N8: =SUM(B8:M8) -> 851521.77
A9: (−) Impostos sobre a receita | B9: =B8*Premissas!$C$9 -> 4800 | C9: =C8*Premissas!$C$9 -> 4944 | D9: =D8*Premissas!$C$9 -> 5092.32 | E9: =E8*Premissas!$C$9 -> 5245.0896 | F9: =F8*Premissas!$C$9 -> 5402.4423 | G9: =G8*Premissas!$C$9 -> 5564.5156 | H9: =H8*Premissas!$C$9 -> 5731.451 | I9: =I8*Premissas!$C$9 -> 5903.3946 | ... M9: =M8*Premissas!$C$9 -> 6644.3226 | N9: =SUM(B9:M9) -> 68121.742
A10: (−) Custos variáveis | B10: =B8*Premissas!$C$8 -> 22800 | C10: =C8*Premissas!$C$8 -> 23484 | D10: =D8*Premissas!$C$8 -> 24188.52 | E10: =E8*Premissas!$C$8 -> 24914.176 | F10: =F8*Premissas!$C$8 -> 25661.601 | G10: =G8*Premissas!$C$8 -> 26431.449 | H10: =H8*Premissas!$C$8 -> 27224.392 | I10: =I8*Premissas!$C$8 -> 28041.124 | ... M10: =M8*Premissas!$C$8 -> 31560.532 | N10: =SUM(B10:M10) -> 323578.27
A11: (=) Margem de contribuição | B11: =B8-B9-B10 -> 32400 | C11: =C8-C9-C10 -> 33372 | D11: =D8-D9-D10 -> 34373.16 | E11: =E8-E9-E10 -> 35404.355 | F11: =F8-F9-F10 -> 36466.485 | G11: =G8-G9-G10 -> 37560.48 | H11: =H8-H9-H10 -> 38687.294 | I11: =I8-I9-I10 -> 39847.913 | ... M11: =M8-M9-M10 -> 44849.177 | N11: =SUM(B11:M11) -> 459821.76
A12: Margem de contribuição % | B12: =IFERROR(B11/B8,0) -> 0.54 | C12: =IFERROR(C11/C8,0) -> 0.54 | D12: =IFERROR(D11/D8,0) -> 0.54 | E12: =IFERROR(E11/E8,0) -> 0.54 | F12: =IFERROR(F11/F8,0) -> 0.54 | G12: =IFERROR(G11/G8,0) -> 0.54 | H12: =IFERROR(H11/H8,0) -> 0.54 | I12: =IFERROR(I11/I8,0) -> 0.54 | ... N12: =IFERROR(N11/N8,0) -> 0.54
A13: (−) Despesas fixas | B13: =Premissas!$C$22 -> 30000 | C13: =Premissas!$C$22 -> 30000 | D13: =Premissas!$C$22 -> 30000 | E13: =Premissas!$C$22 -> 30000 | F13: =Premissas!$C$22 -> 30000 | G13: =Premissas!$C$22 -> 30000 | H13: =Premissas!$C$22 -> 30000 | I13: =Premissas!$C$22 -> 30000 | ... M13: =Premissas!$C$22 -> 30000 | N13: =SUM(B13:M13) -> 360000
A14: (=) EBITDA | B14: =B11-B13 -> 2400 | C14: =C11-C13 -> 3372 | D14: =D11-D13 -> 4373.16 | E14: =E11-E13 -> 5404.3548 | F14: =F11-F13 -> 6466.4854 | G14: =G11-G13 -> 7560.48 | H14: =H11-H13 -> 8687.2944 | I14: =I11-I13 -> 9847.9132 | ... M14: =M11-M13 -> 14849.177 | N14: =SUM(B14:M14) -> 99821.758
A15: Margem EBITDA % | B15: =IFERROR(B14/B8,0) -> 0.04 | C15: =IFERROR(C14/C8,0) -> 0.054563107 | D15: =IFERROR(D14/D8,0) -> 0.068702045 | E15: =IFERROR(E14/E8,0) -> 0.08242917 | F15: =IFERROR(F14/F8,0) -> 0.095756476 | G15: =IFERROR(G14/G8,0) -> 0.10869561 | H15: =IFERROR(H14/H8,0) -> 0.12125787 | I15: =IFERROR(I14/I8,0) -> 0.13345424 | ... N15: =IFERROR(N14/N8,0) -> 0.11722749
A16: (−) Investimentos | B16: =Premissas!$D$26 -> 8000 | C16: =Premissas!$D$27 -> 0 | D16: =Premissas!$D$28 -> 0 | E16: =Premissas!$D$29 -> 3500 | F16: =Premissas!$D$30 -> 0 | G16: =Premissas!$D$31 -> 0 | H16: =Premissas!$D$32 -> 0 | I16: =Premissas!$D$33 -> 0 | J16: =Premissas!$D$34 -> 12000 | K16: =Premissas!$D$35 -> 0 | L16: =Premissas!$D$36 -> 0 | M16: =Premissas!$D$37 -> 0 | N16: =SUM(B16:M16) -> 23500
A17: (=) Fluxo de caixa do mês | B17: =B14-B16 -> -5600 | C17: =C14-C16 -> 3372 | D17: =D14-D16 -> 4373.16 | E17: =E14-E16 -> 1904.3548 | F17: =F14-F16 -> 6466.4854 | G17: =G14-G16 -> 7560.48 | H17: =H14-H16 -> 8687.2944 | I17: =I14-I16 -> 9847.9132 | ... M17: =M14-M16 -> 14849.177 | N17: =SUM(B17:M17) -> 76321.758
A18: Caixa acumulado | B18: =Premissas!$C$10+B17 -> 19400 | C18: =B18+C17 -> 22772 | D18: =C18+D17 -> 27145.16 | E18: =D18+E17 -> 29049.515 | F18: =E18+F17 -> 35516 | G18: =F18+G17 -> 43076.48 | H18: =G18+H17 -> 51763.775 | I18: =H18+I17 -> 61611.688 | J18: =I18+J17 -> 60655.039 | ... M18: =L18+M17 -> 101321.76 | N18: =M18 -> 101321.76
A20: Resumo do cenário ativo
A21: Caixa final após 12 meses (R$) | B21: =M18 -> 101321.76
A22: Menor caixa acumulado no período (R$) | B22: =MIN(B18:M18) -> 19400
A23: Mês do menor caixa | B23: =INDEX(B6:M6,MATCH(MIN(B18:M18),B18:M18,0)) -> Mês 1
A24: Necessidade de capital de giro (se caixa negativo) (R$) | B24: =MAX(0,-MIN(B18:M18)) -> 0
A25: Receita média mensal (R$) | B25: =N8/12 -> 70960.148
A26: Ponto de equilíbrio mensal (R$) = despesas fixas ÷ MC % | B26: =IFERROR(Premissas!$C$22/(1-Premissas!$C$9-Premissas!$C$8),0) -> 55555.556
A27: Mês em que a receita supera o ponto de equilíbrio | B27: =IFERROR(INDEX(B6:M6,MATCH(TRUE(),INDEX(B8:M8>=B26,0),0)),"Não atinge") -> Mês 1

Sheet Cenários
A1: Comparativo de Cenários
A2: Totais de 12 meses para cada cenário, calculados a partir das Premissas (independente do cenário selecionado).
A4: Indicador (12 meses) | B4: Pessimista | C4: Base | D4: Otimista
A5: Crescimento mensal efetivo | B5: =Premissas!$E$44 -> 0.01 | C5: =Premissas!$E$45 -> 0.03 | D5: =Premissas!$E$46 -> 0.05
A6: Receita total (R$) | B6: =N22 -> 684855.16 | C6: =N25 -> 851521.77 | D6: =N28 -> 1050530.4
A7: (−) Impostos sobre a receita (R$) | B7: =N22*Premissas!$C$9 -> 54788.413 | C7: =N25*Premissas!$C$9 -> 68121.742 | D7: =N28*Premissas!$C$9 -> 84042.428
A8: (−) Custos variáveis (R$) | B8: =N22*Premissas!$C$8 -> 260244.96 | C8: =N25*Premissas!$C$8 -> 323578.27 | D8: =N28*Premissas!$C$8 -> 399201.53
A9: (=) Margem de contribuição (R$) | B9: =B6-B7-B8 -> 369821.79 | C9: =C6-C7-C8 -> 459821.76 | D9: =D6-D7-D8 -> 567286.39
A10: (−) Despesas fixas (R$) | B10: =Premissas!$C$22*12 -> 360000 | C10: =Premissas!$C$22*12 -> 360000 | D10: =Premissas!$C$22*12 -> 360000
A11: (=) EBITDA (R$) | B11: =B9-B10 -> 9821.7879 | C11: =C9-C10 -> 99821.758 | D11: =D9-D10 -> 207286.39
A12: Margem EBITDA % | B12: =IFERROR(B11/B6,0) -> 0.014341409 | C12: =IFERROR(C11/C6,0) -> 0.11722749 | D12: =IFERROR(D11/D6,0) -> 0.19731595
A13: (−) Investimentos (R$) | B13: =Premissas!$D$38 -> 23500 | C13: =Premissas!$D$38 -> 23500 | D13: =Premissas!$D$38 -> 23500
A14: (=) Fluxo de caixa acumulado no ano (R$) | B14: =N23 -> -13678.212 | C14: =N26 -> 76321.758 | D14: =N29 -> 183786.39
A15: Caixa final após 12 meses (R$) | B15: =N24 -> 11321.788 | C15: =N27 -> 101321.76 | D15: =N30 -> 208786.39
A16: Menor caixa acumulado no período (R$) | B16: =MIN(B24:M24) -> 4686.2551 | C16: =MIN(B27:M27) -> 19400 | D16: =MIN(B30:M30) -> 22640
A17: Necessidade de capital de giro (R$) | B17: =MAX(0,-B16) -> 0 | C17: =MAX(0,-C16) -> 0 | D17: =MAX(0,-D16) -> 0
A19: Cenário selecionado atualmente na aba Premissas: | B19: =Premissas!$C$41 -> Base
A20: Detalhamento mensal por cenário (R$)
A21: Linha | B21: Mês 1 | C21: Mês 2 | D21: Mês 3 | E21: Mês 4 | F21: Mês 5 | G21: Mês 6 | H21: Mês 7 | I21: Mês 8 | J21: Mês 9 | K21: Mês 10 | L21: Mês 11 | M21: Mês 12 | N21: Total
A22: Pessimista – Receita | B22: =Premissas!$C$6*(1+Premissas!$D$44) -> 54000 | C22: =B22*(1+Premissas!$E$44) -> 54540 | D22: =C22*(1+Premissas!$E$44) -> 55085.4 | E22: =D22*(1+Premissas!$E$44) -> 55636.254 | F22: =E22*(1+Premissas!$E$44) -> 56192.617 | G22: =F22*(1+Premissas!$E$44) -> 56754.543 | H22: =G22*(1+Premissas!$E$44) -> 57322.088 | I22: =H22*(1+Premissas!$E$44) -> 57895.309 | J22: =I22*(1+Premissas!$E$44) -> 58474.262 | ... M22: =L22*(1+Premissas!$E$44) -> 60246.091 | N22: =SUM(B22:M22) -> 684855.16
A23: Pessimista – Fluxo de caixa do mês | B23: =B22*(1-Premissas!$C$9-Premissas!$C$8)-Premissas!$C$22-Premissas!$D$26 -> -8840 | C23: =C22*(1-Premissas!$C$9-Premissas!$C$8)-Premissas!$C$22-Premissas!$D$27 -> -548.4 | D23: =D22*(1-Premissas!$C$9-Premissas!$C$8)-Premissas!$C$22-Premissas!$D$28 -> -253.884 | E23: =E22*(1-Premissas!$C$9-Premissas!$C$8)-Premissas!$C$22-Premissas!$D$29 -> -3456.4228 | F23: =F22*(1-Premissas!$C$9-Premissas!$C$8)-Premissas!$C$22-Premissas!$D$30 -> 344.01293 | G23: =G22*(1-Premissas!$C$9-Premissas!$C$8)-Premissas!$C$22-Premissas!$D$31 -> 647.45306 | H23: =H22*(1-Premissas!$C$9-Premissas!$C$8)-Premissas!$C$22-Premissas!$D$32 -> 953.92759 | I23: =I22*(1-Premissas!$C$9-Premissas!$C$8)-Premissas!$C$22-Premissas!$D$33 -> 1263.4669 | J23: =J22*(1-Premissas!$C$9-Premissas!$C$8)-Premissas!$C$22-Premissas!$D$34 -> -10423.898 | K23: =K22*(1-Premissas!$C$9-Premissas!$C$8)-Premissas!$C$22-Premissas!$D$35 -> 1891.8626 | L23: =L22*(1-Premissas!$C$9-Premissas!$C$8)-Premissas!$C$22-Premissas!$D$36 -> 2210.7812 | M23: =M22*(1-Premissas!$C$9-Premissas!$C$8)-Premissas!$C$22-Premissas!$D$37 -> 2532.889 | N23: =SUM(B23:M23) -> -13678.212
A24: Pessimista – Caixa acumulado | B24: =Premissas!$C$10+B23 -> 16160 | C24: =B24+C23 -> 15611.6 | D24: =C24+D23 -> 15357.716 | E24: =D24+E23 -> 11901.293 | F24: =E24+F23 -> 12245.306 | G24: =F24+G23 -> 12892.759 | H24: =G24+H23 -> 13846.687 | I24: =H24+I23 -> 15110.154 | J24: =I24+J23 -> 4686.2551 | ... M24: =L24+M23 -> 11321.788 | N24: =M24 -> 11321.788
A25: Base – Receita | B25: =Premissas!$C$6*(1+Premissas!$D$45) -> 60000 | C25: =B25*(1+Premissas!$E$45) -> 61800 | D25: =C25*(1+Premissas!$E$45) -> 63654 | E25: =D25*(1+Premissas!$E$45) -> 65563.62 | F25: =E25*(1+Premissas!$E$45) -> 67530.529 | G25: =F25*(1+Premissas!$E$45) -> 69556.444 | H25: =G25*(1+Premissas!$E$45) -> 71643.138 | I25: =H25*(1+Premissas!$E$45) -> 73792.432 | J25: =I25*(1+Premissas!$E$45) -> 76006.205 | ... M25: =L25*(1+Premissas!$E$45) -> 83054.032 | N25: =SUM(B25:M25) -> 851521.77
A26: Base – Fluxo de caixa do mês | B26: =B25*(1-Premissas!$C$9-Premissas!$C$8)-Premissas!$C$22-Premissas!$D$26 -> -5600 | C26: =C25*(1-Premissas!$C$9-Premissas!$C$8)-Premissas!$C$22-Premissas!$D$27 -> 3372 | D26: =D25*(1-Premissas!$C$9-Premissas!$C$8)-Premissas!$C$22-Premissas!$D$28 -> 4373.16 | E26: =E25*(1-Premissas!$C$9-Premissas!$C$8)-Premissas!$C$22-Premissas!$D$29 -> 1904.3548 | F26: =F25*(1-Premissas!$C$9-Premissas!$C$8)-Premissas!$C$22-Premissas!$D$30 -> 6466.4854 | G26: =G25*(1-Premissas!$C$9-Premissas!$C$8)-Premissas!$C$22-Premissas!$D$31 -> 7560.48 | H26: =H25*(1-Premissas!$C$9-Premissas!$C$8)-Premissas!$C$22-Premissas!$D$32 -> 8687.2944 | I26: =I25*(1-Premissas!$C$9-Premissas!$C$8)-Premissas!$C$22-Premissas!$D$33 -> 9847.9132 | J26: =J25*(1-Premissas!$C$9-Premissas!$C$8)-Premissas!$C$22-Premissas!$D$34 -> -956.64936 | K26: =K25*(1-Premissas!$C$9-Premissas!$C$8)-Premissas!$C$22-Premissas!$D$35 -> 12274.651 | L26: =L25*(1-Premissas!$C$9-Premissas!$C$8)-Premissas!$C$22-Premissas!$D$36 -> 13542.891 | M26: =M25*(1-Premissas!$C$9-Premissas!$C$8)-Premissas!$C$22-Premissas!$D$37 -> 14849.177 | N26: =SUM(B26:M26) -> 76321.758
A27: Base – Caixa acumulado | B27: =Premissas!$C$10+B26 -> 19400 | C27: =B27+C26 -> 22772 | D27: =C27+D26 -> 27145.16 | E27: =D27+E26 -> 29049.515 | F27: =E27+F26 -> 35516 | G27: =F27+G26 -> 43076.48 | H27: =G27+H26 -> 51763.775 | I27: =H27+I26 -> 61611.688 | J27: =I27+J26 -> 60655.039 | ... M27: =L27+M26 -> 101321.76 | N27: =M27 -> 101321.76
A28: Otimista – Receita | B28: =Premissas!$C$6*(1+Premissas!$D$46) -> 66000 | C28: =B28*(1+Premissas!$E$46) -> 69300 | D28: =C28*(1+Premissas!$E$46) -> 72765 | E28: =D28*(1+Premissas!$E$46) -> 76403.25 | F28: =E28*(1+Premissas!$E$46) -> 80223.413 | G28: =F28*(1+Premissas!$E$46) -> 84234.583 | H28: =G28*(1+Premissas!$E$46) -> 88446.312 | I28: =H28*(1+Premissas!$E$46) -> 92868.628 | J28: =I28*(1+Premissas!$E$46) -> 97512.059 | ... M28: =L28*(1+Premissas!$E$46) -> 112882.4 | N28: =SUM(B28:M28) -> 1050530.4
A29: Otimista – Fluxo de caixa do mês | B29: =B28*(1-Premissas!$C$9-Premissas!$C$8)-Premissas!$C$22-Premissas!$D$26 -> -2360 | C29: =C28*(1-Premissas!$C$9-Premissas!$C$8)-Premissas!$C$22-Premissas!$D$27 -> 7422 | D29: =D28*(1-Premissas!$C$9-Premissas!$C$8)-Premissas!$C$22-Premissas!$D$28 -> 9293.1 | E29: =E28*(1-Premissas!$C$9-Premissas!$C$8)-Premissas!$C$22-Premissas!$D$29 -> 7757.755 | F29: =F28*(1-Premissas!$C$9-Premissas!$C$8)-Premissas!$C$22-Premissas!$D$30 -> 13320.643 | G29: =G28*(1-Premissas!$C$9-Premissas!$C$8)-Premissas!$C$22-Premissas!$D$31 -> 15486.675 | H29: =H28*(1-Premissas!$C$9-Premissas!$C$8)-Premissas!$C$22-Premissas!$D$32 -> 17761.009 | I29: =I28*(1-Premissas!$C$9-Premissas!$C$8)-Premissas!$C$22-Premissas!$D$33 -> 20149.059 | J29: =J28*(1-Premissas!$C$9-Premissas!$C$8)-Premissas!$C$22-Premissas!$D$34 -> 10656.512 | K29: =K28*(1-Premissas!$C$9-Premissas!$C$8)-Premissas!$C$22-Premissas!$D$35 -> 25289.338 | L29: =L28*(1-Premissas!$C$9-Premissas!$C$8)-Premissas!$C$22-Premissas!$D$36 -> 28053.804 | M29: =M28*(1-Premissas!$C$9-Premissas!$C$8)-Premissas!$C$22-Premissas!$D$37 -> 30956.495 | N29: =SUM(B29:M29) -> 183786.39
A30: Otimista – Caixa acumulado | B30: =Premissas!$C$10+B29 -> 22640 | C30: =B30+C29 -> 30062 | D30: =C30+D29 -> 39355.1 | E30: =D30+E29 -> 47112.855 | F30: =E30+F29 -> 60433.498 | G30: =F30+G29 -> 75920.173 | H30: =G30+H29 -> 93681.181 | I30: =H30+I29 -> 113830.24 | J30: =I30+J29 -> 124486.75 | ... M30: =L30+M29 -> 208786.39 | N30: =M30 -> 208786.39
